<?xml version='1.0' encoding='utf-8'?>
<sdf version="1.9">
    <model name="ackermann_model" canonical_link='base_link' >
        <static>false</static>
        <self_collide>0</self_collide>
        <!-- *********************** Base link/ chassis ************************  -->
        <link name="base_link">
            <pose>0 0 0 0 0 0 </pose>
            <inertial>
                <mass>228.08107716389222</mass>
                <pose>-0.002506114497942632 0.0059847209206220124 0.13111214920079986 0 0 0 </pose>
                <inertia>
                    <ixx>5.372266243151038</ixx>
                    <iyy>2.63294368027065</iyy>
                    <izz>6.461930915740031</izz>
                    <ixy>1.9034836949087097e-05</ixy>
                    <iyz>-0.26217253614499947</iyz>
                    <ixz>-6.779852956771693e-05</ixz>
                </inertia>
            </inertial>
            <visual name="base_link_visual">
                <geometry>
                    <mesh>
                        <uri>package://ackermann_sitl_models/models/ackermann_model/meshes/base_link.stl</uri>
                        <scale>0.001 0.001 0.001</scale>
                    </mesh>
                </geometry>
                <material>
                    <ambient>0.45 0.106 0.202 1</ambient>
                    <diffuse>0.45 0.106 0.202 1</diffuse>
                    <specular>0.45 0.106 0.202 1</specular>
                </material>
            </visual>
            <collision name="base_link_collision">
                <geometry>
                    <mesh>
                        <uri>package://ackermann_sitl_models/models/ackermann_model/meshes/base_link.stl</uri>
                        <scale>0.001 0.001 0.001</scale>
                    </mesh>
                </geometry>
            </collision>
            <sensor name="imu_sensor" type="imu">
                <pose degrees="true">0 0 0 180 0 0</pose>
                <topic>imu</topic>
                <always_on>1</always_on>
                <update_rate>1000 </update_rate>
            </sensor>
        </link>

        <!-- *********************** Wheels ************************  -->
        <link name="wheel_lf">
            <pose>0.17 -0.2014730453491211 0.05496452331542969 6.123233995736766e-17 0 0</pose>
            <inertial>
                <mass>2.955524638350332</mass>
                <pose>0.019999999999999983 -5.438524293787564e-34 -8.881784197001253e-18 0 0 0 </pose>
                <inertia>
                    <ixx>0.004430491910682538</ixx>
                    <iyy>0.002602934841100607</iyy>
                    <izz>0.0026029348411006903</izz>
                    <ixy>-2.7755575615628914e-17</ixy>
                    <iyz>6.938893903907233e-18</iyz>
                    <ixz>-3.4694469519536126e-18</ixz>
                </inertia>
            </inertial>
            <visual name="wheel_lf_visual">
                <geometry>
                    <mesh>
                        <uri>package://ackermann_sitl_models/models/ackermann_model/meshes/wheel_lf.stl</uri>
                        <scale>0.001 0.001 0.001</scale>
                    </mesh>
                </geometry>
                <material>
                    <ambient>0 0 0 1</ambient>
                    <diffuse>0 0 0 1</diffuse>
                    <specular>0 0 0 1</specular>
                </material>
            </visual>
            <collision name="wheel_lf_collision">
                <geometry>
                    <mesh>
                        <uri>package://ackermann_sitl_models/models/ackermann_model/meshes/wheel_lf.stl</uri>
                        <scale>0.001 0.001 0.001</scale>
                    </mesh>
                </geometry>
                <surface>
                    <friction>
                        <ode>
                            <mu>0.5</mu>
                            <mu2>1.0</mu2>
                            <fdir1>0 0 1</fdir1>
                        </ode>
                    </friction>
                </surface>
            </collision>
        </link>
        <link name="wheel_rf">
            <pose>-0.17 -0.2014730453491211 0.05496452331542969 6.123233995736766e-17 0 0</pose>
            <inertial>
                <mass>2.955524638350332</mass>
                <pose>-0.02 5.438524293787564e-34 8.881784197001253e-18 0 0 0 </pose>
                <inertia>
                    <ixx>0.004430491910682538</ixx>
                    <iyy>0.0026029348411006348</iyy>
                    <izz>0.0026029348411006903</izz>
                    <ixy>2.1244235522607673e-34</ixy>
                    <iyz>6.938893903907231e-18</iyz>
                    <ixz>3.469446951953614e-18</ixz>
                </inertia>
            </inertial>
            <visual name="wheel_rf_visual">
                <geometry>
                    <mesh>
                        <uri>package://ackermann_sitl_models/models/ackermann_model/meshes/wheel_rf.stl</uri>
                        <scale>0.001 0.001 0.001</scale>
                    </mesh>
                </geometry>
                <material>
                    <ambient>0 0 0 1</ambient>
                    <diffuse>0 0 0 1</diffuse>
                    <specular>0 0 0 1</specular>
                </material>
            </visual>
            <collision name="wheel_rf_collision">
                <geometry>
                    <mesh>
                        <uri>package://ackermann_sitl_models/models/ackermann_model/meshes/wheel_rf.stl</uri>
                        <scale>0.001 0.001 0.001</scale>
                    </mesh>
                </geometry>
                <surface>
                    <friction>
                        <ode>
                            <mu>0.5</mu>
                            <mu2>1.0</mu2>
                            <fdir1>0 0 1</fdir1>
                        </ode>
                    </friction>
                </surface>
            </collision>
        </link>
        <link name="wheel_lb">
            <pose>0.17 0.1890655040740967 0.05488921642303467 6.123233995736766e-17 0 0</pose>
            <inertial>
                <mass>2.955524638350332</mass>
                <pose>0.02 5.438524293787564e-34 8.881784197001253e-18 0 0 0 </pose>
                <inertia>
                    <ixx>0.004430491910682538</ixx>
                    <iyy>0.0026029348411006348</iyy>
                    <izz>0.0026029348411006903</izz>
                    <ixy>1.3877787807814457e-17</ixy>
                    <iyz>3.394451526982503e-33</iyz>
                    <ixz>-3.469446951953615e-18</ixz>
                </inertia>
            </inertial>
            <visual name="wheel_lb_visual">
                <geometry>
                    <mesh>
                        <uri>package://ackermann_sitl_models/models/ackermann_model/meshes/wheel_lb.stl</uri>
                        <scale>0.001 0.001 0.001</scale>
                    </mesh>
                </geometry>
                <material>
                    <ambient>0 0 0 1</ambient>
                    <diffuse>0 0 0 1</diffuse>
                    <specular>0 0 0 1</specular>
                </material>
            </visual>
            <collision name="wheel_lb_collision">
                <geometry>
                    <mesh>
                        <uri>package://ackermann_sitl_models/models/ackermann_model/meshes/wheel_lb.stl</uri>
                        <scale>0.001 0.001 0.001</scale>
                    </mesh>
                </geometry>
                <surface>
                    <friction>
                        <ode>
                            <mu>0.5</mu>
                            <mu2>1.0</mu2>
                            <fdir1>0 0 1</fdir1>
                        </ode>
                    </friction>
                </surface>
            </collision>
        </link>
        <link name="wheel_rb">
            <pose>-0.17 0.1890655040740967 0.05488921642303467 6.123233995736766e-17 0 0</pose>
            <inertial>
                <mass>2.9555246383503317</mass>
                <pose>-0.02 0 0 0 0 0</pose>
                <inertia>
                    <ixx>0.004430491910682566</ixx>
                    <iyy>0.0026029348411006348</iyy>
                    <izz>0.0026029348411006903</izz>
                    <ixy>0 </ixy>
                    <iyz>-3.4694469519536107e-18</iyz>
                    <ixz>0 </ixz>
                </inertia>
            </inertial>
            <visual name="wheel_rb_visual">
                <geometry>
                    <mesh>
                        <uri>package://ackermann_sitl_models/models/ackermann_model/meshes/wheel_rb.stl</uri>
                        <scale>0.001 0.001 0.001</scale>
                    </mesh>
                </geometry>
                <material>
                    <ambient>0 0 0 1</ambient>
                    <diffuse>0 0 0 1</diffuse>
                    <specular>0 0 0 1</specular>
                </material>
            </visual>
            <collision name="wheel_rb_collision">
                <geometry>
                    <mesh>
                        <uri>package://ackermann_sitl_models/models/ackermann_model/meshes/wheel_rb.stl</uri>
                        <scale>0.001 0.001 0.001</scale>
                    </mesh>
                </geometry>
                <surface>
                    <friction>
                        <ode>
                            <mu>0.5</mu>
                            <mu2>1.0</mu2>
                            <fdir1>0 0 1</fdir1>
                        </ode>
                    </friction>
                </surface>
            </collision>
        </link>

        <!-- *********************** Sonar ************************  -->
        <link name="sonar_mid_b">
            <pose>0 0.2784625381183624 0.05021122360229493 0 0 3.141592653589793</pose>
            <inertial>
                <mass>0.02355</mass>
                <pose>0 0 -0.0002499999999999947 0 0 0 </pose>
                <inertia>
                    <ixx>1.2442250000000397e-06</ixx>
                    <iyy>4.366562499999987e-06</iyy>
                    <izz>3.1576625000003314e-06</izz>
                    <ixy>-4.357625371653739e-22</ixy>
                    <iyz>0 </iyz>
                    <ixz>0 </ixz>
                </inertia>
            </inertial>
            <visual name="sonar_mid_b_visual">
                <geometry>
                    <mesh>
                        <uri>package://ackermann_sitl_models/models/ackermann_model/meshes/sonar_mid_b.stl</uri>
                        <scale>0.001 0.001 0.001</scale>
                    </mesh>
                </geometry>
            </visual>
            <collision name="sonar_mid_b_collision">
                <geometry>
                    <mesh>
                        <uri>package://ackermann_sitl_models/models/ackermann_model/meshes/sonar_mid_b.stl</uri>
                        <scale>0.001 0.001 0.001</scale>
                    </mesh>
                </geometry>
            </collision>
            <sensor name='sonar_mid_b_sensor' type='gpu_lidar'>
                <gz_frame_id>sonar_mid_b</gz_frame_id>
                <pose>0 0 0 0 0 -1.570796</pose>
                <always_on>1</always_on>
                <visualize>true</visualize>
                <topic>sonar_back_mid</topic>

                <update_rate>20</update_rate>
                <ray>
                    <scan>
                        <vertical>
                            <samples>1</samples>
                            <resolution>1</resolution>
                            <min_angle>0</min_angle>
                            <max_angle>0</max_angle>
                        </vertical>
                        <horizontal>
                            <samples>5</samples>
                            <resolution>1</resolution>
                            <min_angle>-0.14835</min_angle>
                            <max_angle>0.14835</max_angle>
                        </horizontal>
                    </scan>
                    <range>
                        <min>0.01</min>
                        <max>2</max>
                        <resolution>0.02</resolution>
                    </range>
                    <noise>
                        <type>gaussian</type>
                        <mean>0.1</mean>
                        <stddev>0.05</stddev>
                    </noise>
                </ray>
            </sensor>
        </link>

        <link name="sonar_l">
            <pose>0.15685000000000002 -0.08590745388221742 0.028147066354751588 3.141592653589793 1.2246467991473532e-16 3.141592653589793</pose>
            <inertial>
                <mass>0.02355</mass>
                <pose>-0.00025000000000000364 0 -0.0004999999999999938 0 0 0 </pose>
                <inertia>
                    <ixx>4.366562500000007e-06</ixx>
                    <iyy>1.2442250000000397e-06</iyy>
                    <izz>3.157662500000006e-06</izz>
                    <ixy>5.421010862427522e-20</ixy>
                    <iyz>-6.638823600814898e-36</iyz>
                    <ixz>-2.7253101863686535e-20</ixz>
                </inertia>
            </inertial>
            <visual name="sonar_l_visual">
                <geometry>
                    <mesh>
                        <uri>package://ackermann_sitl_models/models/ackermann_model/meshes/sonar_l.stl</uri>
                        <scale>0.001 0.001 0.001</scale>
                    </mesh>
                </geometry>
            </visual>
            <collision name="sonar_l_collision">
                <geometry>
                    <mesh>
                        <uri>package://ackermann_sitl_models/models/ackermann_model/meshes/sonar_l.stl</uri>
                        <scale>0.001 0.001 0.001</scale>
                    </mesh>
                </geometry>
            </collision>
            <sensor name='sonar_l_sensor' type='gpu_lidar'>
                <pose>0 0 0 0 0 3.141593</pose>
                <always_on>1</always_on>
                <visualize>true</visualize>

                <gz_frame_id>sonar_l</gz_frame_id>
                <topic>sonar_left</topic>
                <update_rate>20</update_rate>
                <ray>
                    <scan>
                        <vertical>
                            <samples>1</samples>
                            <resolution>1</resolution>
                            <min_angle>0</min_angle>
                            <max_angle>0</max_angle>
                        </vertical>
                        <horizontal>
                            <samples>5</samples>
                            <resolution>1</resolution>
                            <min_angle>-0.14835</min_angle>
                            <max_angle>0.14835</max_angle>
                        </horizontal>
                    </scan>
                    <range>
                        <min>0.01</min>
                        <max>2</max>
                        <resolution>0.02</resolution>
                    </range>
                    <noise>
                        <type>gaussian</type>
                        <mean>0.1</mean>
                        <stddev>0.05</stddev>
                    </noise>
                </ray>
            </sensor>
        </link>

        <link name="sonar_rb">
            <pose>-0.12010000000000001 0.2784625381183624 0.05021122360229493 3.141592653589793 0 0 </pose>
            <inertial>
                <mass>0.02355</mass>
                <pose>0 -3.061616997868318e-20 0.0002499999999999947 0 0 0 </pose>
                <inertia>
                    <ixx>1.2442250000000397e-06</ixx>
                    <iyy>4.366562499999926e-06</iyy>
                    <izz>3.1576625000003314e-06</izz>
                    <ixy>-1.0842021724855044e-19</ixy>
                    <iyz>1.4804755154887391e-22</iyz>
                    <ixz>-1.3277647201629795e-35</ixz>
                </inertia>
            </inertial>
            <visual name="sonar_rb_visual">
                <geometry>
                    <mesh>
                        <uri>package://ackermann_sitl_models/models/ackermann_model/meshes/sonar_rb.stl</uri>
                        <scale>0.001 0.001 0.001</scale>
                    </mesh>
                </geometry>
            </visual>
            <collision name="sonar_rb_collision">
                <geometry>
                    <mesh>
                        <uri>package://ackermann_sitl_models/models/ackermann_model/meshes/sonar_rb.stl</uri>
                        <scale>0.001 0.001 0.001</scale>
                    </mesh>
                </geometry>
            </collision>
            <sensor name='sonar_rb_sensor' type='gpu_lidar'>
                <pose>0 0 0 0 0 -1.570796</pose>
                <always_on>1</always_on>
                <visualize>true</visualize>
                <topic>sonar_back_right</topic>
                <gz_frame_id>sonar_rb</gz_frame_id>
                <update_rate>20</update_rate>
                <ray>
                    <scan>
                        <vertical>
                            <samples>1</samples>
                            <resolution>1</resolution>
                            <min_angle>0</min_angle>
                            <max_angle>0</max_angle>
                        </vertical>
                        <horizontal>
                            <samples>5</samples>
                            <resolution>1</resolution>
                            <min_angle>-0.14835</min_angle>
                            <max_angle>0.14835</max_angle>
                        </horizontal>
                    </scan>
                    <range>
                        <min>0.01</min>
                        <max>2</max>
                        <resolution>0.02</resolution>
                    </range>
                    <noise>
                        <type>gaussian</type>
                        <mean>0.1</mean>
                        <stddev>0.05</stddev>
                    </noise>
                </ray>
            </sensor>
        </link>

        <link name="sonar_r">
            <pose>-0.16185000000000002 -0.08590745388221742 0.028147066354751598 0 0 0 </pose>
            <inertial>
                <mass>0.02355</mass>
                <pose>-0.0002499999999999858 0 0.0004999999999999983 0 0 0 </pose>
                <inertia>
                    <ixx>4.366562499999953e-06</ixx>
                    <iyy>1.244224999999823e-06</iyy>
                    <izz>3.1576624999998977e-06</izz>
                    <ixy>0 </ixy>
                    <iyz>6.776263578034403e-21</iyz>
                    <ixz>2.710505431213761e-20</ixz>
                </inertia>
            </inertial>
            <visual name="sonar_r_visual">
                <geometry>
                    <mesh>
                        <uri>package://ackermann_sitl_models/models/ackermann_model/meshes/sonar_r.stl</uri>
                        <scale>0.001 0.001 0.001</scale>
                    </mesh>
                </geometry>
            </visual>
            <collision name="sonar_r_collision">
                <geometry>
                    <mesh>
                        <uri>package://ackermann_sitl_models/models/ackermann_model/meshes/sonar_r.stl</uri>
                        <scale>0.001 0.001 0.001</scale>
                    </mesh>
                </geometry>
            </collision>
            <sensor name='sonar_r_sensor' type='gpu_lidar'>
                <pose>0 0 0 0 0 3.141593</pose>
                <always_on>1</always_on>
                <visualize>true</visualize>
                <topic>sonar_right</topic>
                <gz_frame_id>sonar_r</gz_frame_id>

                <update_rate>20</update_rate>
                <ray>
                    <scan>
                        <vertical>
                            <samples>1</samples>
                            <resolution>1</resolution>
                            <min_angle>0</min_angle>
                            <max_angle>0</max_angle>
                        </vertical>
                        <horizontal>
                            <samples>5</samples>
                            <resolution>1</resolution>
                            <min_angle>-0.14835</min_angle>
                            <max_angle>0.14835</max_angle>
                        </horizontal>
                    </scan>
                    <range>
                        <min>0.01</min>
                        <max>2</max>
                        <resolution>0.02</resolution>
                    </range>
                    <noise>
                        <type>gaussian</type>
                        <mean>0.1</mean>
                        <stddev>0.05</stddev>
                    </noise>
                </ray>
            </sensor>
        </link>

        <link name="sonar_lb">
            <pose>0.11560000000000001 0.2784625381183624 0.05021122360229493 0 7.647924788138762e-33 3.141592653589793</pose>
            <inertial>
                <mass>0.02355</mass>
                <pose>1.91198119703465e-36 0 -0.0002499999999999947 0 0 0 </pose>
                <inertia>
                    <ixx>1.2442250000000397e-06</ixx>
                    <iyy>4.366562499999926e-06</iyy>
                    <izz>3.1576624999998977e-06</izz>
                    <ixy>-2.924383366962545e-54</ixy>
                    <iyz>-2.5386611790376445e-68</iyz>
                    <ixz>-2.710505431213761e-20</ixz>
                </inertia>
            </inertial>
            <visual name="sonar_lb_visual">
                <geometry>
                    <mesh>
                        <uri>package://ackermann_sitl_models/models/ackermann_model/meshes/sonar_lb.stl</uri>
                        <scale>0.001 0.001 0.001</scale>
                    </mesh>
                </geometry>
            </visual>
            <collision name="sonar_lb_collision">
                <geometry>
                    <mesh>
                        <uri>package://ackermann_sitl_models/models/ackermann_model/meshes/sonar_lb.stl</uri>
                        <scale>0.001 0.001 0.001</scale>
                    </mesh>
                </geometry>
            </collision>
            <sensor name='sonar_lb_sensor' type='gpu_lidar'>
                <pose>0 0 0 0 0 -1.570796</pose>
                <always_on>1</always_on>
                <visualize>true</visualize>
                <topic>sonar_back_left</topic>
                <gz_frame_id>sonar_lb</gz_frame_id>

                <update_rate>20</update_rate>
                <ray>
                    <scan>
                        <vertical>
                            <samples>1</samples>
                            <resolution>1</resolution>
                            <min_angle>0</min_angle>
                            <max_angle>0</max_angle>
                        </vertical>
                        <horizontal>
                            <samples>5</samples>
                            <resolution>1</resolution>
                            <min_angle>-0.14835</min_angle>
                            <max_angle>0.14835</max_angle>
                        </horizontal>
                    </scan>
                    <range>
                        <min>0.01</min>
                        <max>2</max>
                        <resolution>0.02</resolution>
                    </range>
                    <noise>
                        <type>gaussian</type>
                        <mean>0.1</mean>
                        <stddev>0.05</stddev>
                    </noise>
                </ray>
            </sensor>
        </link>

        <!-- *********************** Lidar ************************  -->
        <link name="lidar">
            <pose>5.574824817526691e-05 -0.26354743715643186 0.02004215812683105 0 0 0 </pose>
            <inertial>
                <mass>1.1038022659963431</mass>
                <pose>8.083811398051921e-18 0 0.015 0 0 0 </pose>
                <inertia>
                    <ixx>0.0004916472258667259</ixx>
                    <iyy>0.0004916472258667511</iyy>
                    <izz>0.00083214054128046</izz>
                    <ixy>3.5914196963582334e-19</ixy>
                    <iyz>-1.734723475976807e-18</iyz>
                    <ixz>4.446922973085077e-20</ixz>
                </inertia>
            </inertial>
            <visual name="lidar_visual">
                <geometry>
                    <mesh>
                        <uri>package://ackermann_sitl_models/models/ackermann_model/meshes/lidar.stl</uri>
                        <scale>0.001 0.001 0.001</scale>
                    </mesh>
                </geometry>
            </visual>
            <collision name="lidar_collision">
                <geometry>
                    <mesh>
                        <uri>package://ackermann_sitl_models/models/ackermann_model/meshes/lidar.stl</uri>
                        <scale>0.001 0.001 0.001</scale>
                    </mesh>
                </geometry>
            </collision>
            <sensor name='lidar' type='gpu_lidar'>
                <pose >0 0 0 0 0 0</pose>
                <always_on>1</always_on>
                <topic>lidar</topic>
                <update_rate>10</update_rate>
                <visualize>1</visualize>
                <ray>
                    <scan>
                        <horizontal>
                            <samples>1600</samples>
                            <resolution>1</resolution>
                            <min_angle>-3.141592654</min_angle>
                            <max_angle>3.141592654</max_angle>
                        </horizontal>
                    </scan>
                    <range>
                        <min>0.001</min>
                        <max>40</max>
                        <resolution>0.03</resolution>
                    </range>
                    <noise>
                        <type>gaussian</type>
                        <mean>0</mean>
                        <stddev>0.03</stddev>
                    </noise>
                </ray>
            </sensor>
        </link>

        <!-- *********************** Camera ************************  -->
        <link name="camera">
            <pose>0 -0.0925 0.21 0 0 0 </pose>
            <inertial>
                <mass>0.8882300786905009</mass>
                <pose>1.0047415613648145e-17 -0.006778007253582867 0.010067912331765818 0 0 0 </pose>
                <inertia>
                    <ixx>0.00019183722376594353</ixx>
                    <iyy>0.0006646255142547589</iyy>
                    <izz>0.0006689190053756778</izz>
                    <ixy>2.964869089048247e-19</ixy>
                    <iyz>1.2411990842880333e-05</iyz>
                    <ixz>4.468269160092423e-19</ixz>
                </inertia>
            </inertial>
            <visual name="camera_visual">
                <geometry>
                    <mesh>
                        <uri>package://ackermann_sitl_models/models/ackermann_model/meshes/camera.stl</uri>
                        <scale>0.001 0.001 0.001</scale>
                    </mesh>
                </geometry>
            </visual>
            <collision name="camera_collision">
                <geometry>
                    <mesh>
                        <uri>package://ackermann_sitl_models/models/ackermann_model/meshes/camera.stl</uri>
                        <scale>0.001 0.001 0.001</scale>
                    </mesh>
                </geometry>
            </collision>
            <sensor name="depth_camera" type="rgbd_camera">
                <pose>0 -0.02 0.04 0 0.05235988 -1.570</pose>
                <camera>
                    <horizontal_fov>1.0472</horizontal_fov>
                    <lens>
                        <intrinsics>
                            <!-- fx = fy = width / ( 2 * tan (hfov / 2 ) ) -->
                            <fx>554.25469</fx>
                            <fy>554.25469</fy>
                            <!-- cx = ( width + 1 ) / 2 -->
                            <cx>320.5</cx>
                            <!-- cy = ( height + 1 ) / 2 -->
                            <cy>240.5</cy>
                            <s>0</s>
                        </intrinsics>
                    </lens>
                    <distortion>
                        <k1>0 </k1>
                        <k2>0 </k2>
                        <k3>0 </k3>
                        <p1>0 </p1>
                        <p2>0 </p2>
                        <center>0.5 0.5</center>
                    </distortion>
                    <image>
                        <width>640</width>
                        <height>480</height>
                        <format>R8G8B8</format>
                    </image>
                    <clip>
                        <near>0.02</near>
                        <far>300</far>
                    </clip>
                    <depth_camera>
                        <clip>
                            <near>0.1</near>
                            <far>10</far>
                        </clip>
                    </depth_camera>
                    <noise>
                        <type>gaussian</type>
                        <mean>0</mean>
                        <stddev>0.007</stddev>
                    </noise>
                </camera>
                <always_on>1</always_on>
                <update_rate>60</update_rate>
                <visualize>true</visualize>
                <topic>camera</topic>
            </sensor>
        </link>

        <!-- *********************** steering ************************  -->
        <link name="steering_left">
            <pose>-0.1048816430091858 -0.21355801826286314 0.05496452331542969 3.141592653589793 0 -1.5707963267948966</pose>
            <inertial>
                <mass>0.09419999999999999</mass>
                <pose>0 0 -0.01500000000000001 0 0 0 </pose>
                <inertia>
                    <ixx>1.020500000000011e-05</ixx>
                    <iyy>1.020500000000011e-05</iyy>
                    <izz>6.280000000000001e-06</izz>
                    <ixy>-4.336808689942018e-19</ixy>
                    <iyz>-1.3277647201629795e-35</iyz>
                    <ixz>-2.168404344971009e-19</ixz>
                </inertia>
            </inertial>
            <visual name="steering_left_visual">
                <geometry>
                    <mesh>
                        <uri>package://ackermann_sitl_models/models/ackermann_model/meshes/steering_left.stl</uri>
                        <scale>0.001 0.001 0.001</scale>
                    </mesh>
                </geometry>
            </visual>
        </link>

        <link name="steering_right">
            <pose>0.10412787685394287 -0.21355801826286314 0.05496452331542969 3.141592653589793 0 -1.5707963267948966</pose>
            <inertial>
                <mass>0.09419999999999999</mass>
                <pose>0 0 0.01500000000000001 0 0 0 </pose>
                <inertia>
                    <ixx>1.020500000000011e-05</ixx>
                    <iyy>1.020500000000011e-05</iyy>
                    <izz>6.280000000000868e-06</izz>
                    <ixy>-4.336808689942018e-19</ixy>
                    <iyz>-2.168404344971009e-19</iyz>
                    <ixz>0 </ixz>
                </inertia>
            </inertial>
            <visual name="steering_right_visual">
                <geometry>
                    <mesh>
                        <uri>package://ackermann_sitl_models/models/ackermann_model/meshes/steering_right.stl</uri>
                        <scale>0.001 0.001 0.001</scale>
                    </mesh>
                </geometry>
            </visual>
        </link>
        <!-- *********************** ***************** ************************  -->
        <!-- *********************** Joints ************************  -->
        <joint name="base_link_steering_right" type="revolute">
            <pose>1.231460571293752e-07 1.826286313844072e-08 4.766845703094158e-07 0 0 0 </pose>
            <parent>base_link</parent>
            <child>steering_right</child>
            <axis>
                <xyz>0 0 1</xyz>
                <limit>
                    <lower>-0.6</lower>
                    <upper>0.6</upper>
                    <velocity>1.0</velocity>
                    <effort>25</effort>
                </limit>
            </axis>
        </joint>
        <joint name="base_link_steering_left" type="revolute">
            <pose>-1.231460571293752e-07 1.826286313844072e-08 -4.766845703094158e-07 0 0 0 </pose>
            <parent>base_link</parent>
            <child>steering_left</child>
            <axis>
                <xyz>0 0 1</xyz>
                <limit>
                    <lower>-0.6</lower>
                    <upper>0.6</upper>
                    <velocity>1.0</velocity>
                    <effort>25</effort>
                </limit>
            </axis>
        </joint>
        <joint name="steering_wheel_rf_joint" type="revolute">
            <pose>3.5699081420148543e-07 4.766845703094158e-07 -1.8262863138440745e-08 0 0 0 </pose>
            <parent>steering_right</parent>
            <child>wheel_rf</child>
            <axis>
                <xyz>1 0 0</xyz>
                <limit>
                    <lower>-1e+16</lower>
                    <upper>1e+16</upper>
                </limit>
            </axis>
        </joint>
        <joint name="steering_wheel_lf_joint" type="revolute">
            <pose>-3.5699081420148543e-07 4.766845703094158e-07 -1.8262863138440745e-08 0 0 0 </pose>
            <parent>steering_left</parent>
            <child>wheel_lf</child>
            <axis>
                <xyz>1 0 0</xyz>
                <limit>
                    <lower>-1e+16</lower>
                    <upper>1e+16</upper>
                </limit>
            </axis>
        </joint>
        <joint name="base_link_wheel_lb_joint" type="revolute">
            <pose>0 0 0 0 0 0 </pose>
            <parent>base_link</parent>
            <child>wheel_lb</child>
            <axis>
                <xyz>1 0 0</xyz>
                <limit>
                    <lower>-1e+16</lower>
                    <upper>1e+16</upper>
                </limit>
                <dynamics>
                    <damping>0.0005</damping>
                </dynamics>
            </axis>
        </joint>
        <joint name="base_link_wheel_rb_joint" type="revolute">
            <pose>0 0 0 0 0 0 </pose>
            <parent>base_link</parent>
            <child>wheel_rb</child>
            <axis>
                <xyz>1 0 0</xyz>
                <limit>
                    <lower>-1e+16</lower>
                    <upper>1e+16</upper>
                </limit>
                <dynamics>
                    <damping>0.0005</damping>
                </dynamics>
            </axis>
        </joint>
        <joint name="base_link_lidar_joint" type="fixed">
            <pose>0.0005612517518247331 -0.014592562843568135 0.030249841873168953 0 0 0 </pose>
            <parent>base_link</parent>
            <child>lidar</child>
        </joint>
        <joint name="base_link_camera_joint" type="fixed">
            <pose>-0.0025 -0.03629299999999999 -0.01999999999999999 0 0 0 </pose>
            <parent>base_link</parent>
            <child>camera</child>
        </joint>
        <joint name="base_link_sonar_l_joint" type="fixed">
            <pose>0.0012500000000000304 -0.054999546117782586 0.012000066354751586 0 0 0 </pose>
            <parent>base_link</parent>
            <child>sonar_l</child>
        </joint>
        <joint name="base_link_sonar_r_joint" type="fixed">
            <pose>0.0012500000000000289 -0.054999546117782586 -0.012000066354751596 0 0 0 </pose>
            <parent>base_link</parent>
            <child>sonar_r</child>
        </joint>
        <joint name="base_link_sonar_mid_b" type="fixed">
            <pose>0.0025 0.001499538118362398 -0.012750223602294927 0 0 0 </pose>
            <parent>base_link</parent>
            <child>sonar_mid_b</child>
        </joint>
        <joint name="base_link_sonar_rb" type="fixed">
            <pose>-0.04049999999999998 0.0014995381183623964 0.012750223602294927 0 0 0 </pose>
            <parent>base_link</parent>
            <child>sonar_rb</child>
        </joint>
        <joint name="base_link_sonar_lb" type="fixed">
            <pose>-0.03999999999999998 0.001499538118362398 -0.012750223602294927 0 0 0 </pose>
            <parent>base_link</parent>
            <child>sonar_lb</child>
        </joint>

        <!-- *********************** ***************** ************************  -->
        <!-- **************************** Plugins *****************************  -->

       
    </model>
</sdf>